Workbook

Sheet Hypotheses
A1: NutriScope — TP7 : KPI, coûts & ROI — Hypothèses
A2: Toutes les hypothèses modifiables sont en bleu. Les cellules noires sont des formules qui recalculent automatiquement.
A4: A. Trajectoire MAU — jalons issus de trajectoire_36_mois_nutriscope.csv (TP1)
A5: Mois | B5: Part de marché (%) | C5: MAU
A6: 1 | B6: 0.0004 | C6: 15700
A7: 6 | B7: 0.0058 | C7: 231000
A8: 12 | B8: 0.0164 | C8: 654000
A9: 18 | B9: 0.0301 | C9: 1202000
A10: 24 | B10: 0.0463 | C10: 1850000
A11: 30 | B11: 0.0647 | C11: 2586000
A12: 36 | B12: 0.085 | C12: 3400000
A13: Source : projet NutriScope, fichier trajectoire_36_mois_nutriscope.csv (déjà produit par l'équipe, TP1)
A15: B. Modèle de revenus — repris de benchmark.md (TP6) / synthese_strategique_nutriscope.md
A16: Prix abonnement Premium (€ / mois) | B16: 2.99
A17: ARPU Premium annuel (€ / abonné / an) | B17: =Hypotheses!$B$16*12 -> 35.88
A18: Valeur d'un contrat B2B API/data (€ / an) | B18: 12000
A20: Hypothèse | B20: Pessimiste | C20: Normal (central) | D20: Optimiste
A21: Taux de conversion Premium (% des MAU abonnés) | B21: 0.007 | C21: 0.01 | D21: 0.02
A22: Nombre de contrats B2B actifs sur l'année | B22: 0 | C22: 2 | D22: 5
A23: Note : taux nettement en retrait des moyennes usuelles d'applications freemium grand public — hypothèse prudente tant qu'aucun test réel de vente n'a été mené (voir §8, hypothèses fragiles).
A25: C. Coûts Build (one-off, Année 1) — équipe & données
A26: Nombre d'ETP mobilisés (dev + data, moyenne pondérée) | B26: 3
A27: Coût chargé moyen par ETP (€ / an) | B27: 58000
A28: Durée de mobilisation de l'équipe build (mois, sur 12) | B28: 7
A29: Build - Développement (équipe technique) | B29: =Hypotheses!$B$26*Hypotheses!$B$27*Hypotheses!$B$28/12 -> 101500
A30: Jours-homme nettoyage / qualification / annotation data | B30: 30
A31: Coût journalier interne (€ / jour) | B31: 500
A32: Build - Données (nettoyage, jeux de test, annotation) | B32: =Hypotheses!$B$30*Hypotheses!$B$31 -> 15000
A33: TOTAL BUILD (Année 1) | B33: =Hypotheses!$B$29+Hypotheses!$B$32+Hypotheses!$B$88 -> 136000
A34: Hypothèse de dimensionnement (3 profils, cf. planning note_cadrage.md §5) : 1) données & modèle Nutri-Score (pipeline, base SQL, modèle prédictif, mois 1-3), 2) IA produit (moteur de substitution, assistant RAG, mois 4-5), 3) intégration & déploiement (API FastAPI, Docker, mini-application, mois 6-7). Coût chargé 58 000 €/an : hypothèse de marché (moyenne junior/confirmé, profil data/dev France), pas un chiffre issu d'un document du projet. 30 jours-homme de données : ~10 j nettoyage/qualification, ~10 j constitution des jeux de test, ~10 j annotation manuelle pour évaluer le modèle Nutri-Score et le moteur de substitution. Coût journalier 500 €/jour : hypothèse de TJM (taux journalier moyen) dans la fourchette basse-médiane du marché français pour un profil data/IA freelance ou stage renforcé (ordre de grandeur 400-550 €/jour).
A35: D. Coûts Run (récurrents, proportionnels au MAU du mois) — cf. Module 2.4, iceberg du TCO
A36: Hébergement (API + base + front), € / MAU actif / an | B36: 0.12
A37: Stockage images / cache substitutions, € / MAU actif / an | B37: 0.015
A38: Part des MAU utilisant l'assistant conversationnel / mois | B38: 0.1
A39: Conversations par utilisateur-assistant / mois | B39: 3
A40: Tokens par conversation (entrée+sortie, contexte produit inclus) | B40: 4000
A41: Prix LLM (€ / million de tokens, hypothèse mixte) | B41: 2
A42: ETP supervision / réentraînement des modèles | B42: 0.3
A43: Run - Supervision (annuel, ETP × coût chargé) | B43: =Hypotheses!$B$42*Hypotheses!$B$27 -> 17400
A45: E. Coûts Change (annuels) — acquisition & accompagnement des utilisateurs
...

Sheet MAU_mensuel
A1: Mois | B1: Indice de segment | C1: Année | D1: N° mois calendaire | E1: Mois calendaire | F1: Type | G1: Incrément linéaire du segment | H1: Indice saisonnier appliqué | I1: Incrément brut ajusté | J1: Facteur de recalage (segment) | K1: MAU (trajectoire retenue) | L1: Ce qui influence la hausse/la baisse ce mois-ci
A2: 1 | B2: 1 | C2: =Hypotheses!$B$62+INT((Hypotheses!$B$61-1+(A2-1))/12) -> 2026 | D2: =MOD(Hypotheses!$B$61-1+(A2-1),12)+1 -> 11 | E2: =CHOOSE(D2,"Janvier","Février","Mars","Avril","Mai","Juin","Juillet","Août","Septembre","Octobre","Novembre","Décembre") -> Novembre | F2: =IF(COUNTIF(Hypotheses!$A$6:$A$12,A2)>0,"Jalon","Interpolé") -> Jalon | H2: =INDEX(Hypotheses!$C$65:$C$76,MATCH(D2,Hypotheses!$B$65:$B$76,0)) -> 0 | K2: =INDEX(Hypotheses!$C$6:$C$12,MATCH(A2,Hypotheses!$A$6:$A$12,0)) -> 15700 | L2: ="Point de repère fixé au TP1 (jalon) — valeur non recalculée" -> Point de repère fixé au TP1 (jalon) — valeur non recalculée
A3: 2 | B3: =MATCH(A3-1,Hypotheses!$A$6:$A$12,1) -> 1 | C3: =Hypotheses!$B$62+INT((Hypotheses!$B$61-1+(A3-1))/12) -> 2026 | D3: =MOD(Hypotheses!$B$61-1+(A3-1),12)+1 -> 12 | E3: =CHOOSE(D3,"Janvier","Février","Mars","Avril","Mai","Juin","Juillet","Août","Septembre","Octobre","Novembre","Décembre") -> Décembre | F3: =IF(COUNTIF(Hypotheses!$A$6:$A$12,A3)>0,"Jalon","Interpolé") -> Interpolé | G3: =(INDEX(Hypotheses!$C$6:$C$12,B3+1)-INDEX(Hypotheses!$C$6:$C$12,B3))/(INDEX(Hypotheses!$A$6:$A$12,B3+1)-INDEX(Hypotheses!$A$6:$A$12,B3)) -> 43060 | H3: =INDEX(Hypotheses!$C$65:$C$76,MATCH(D3,Hypotheses!$B$65:$B$76,0)) -> 0.25 | I3: =G3*(1+H3) -> 53825 | J3: =(INDEX(Hypotheses!$C$6:$C$12,B3+1)-INDEX(Hypotheses!$C$6:$C$12,B3))/SUMIFS($I$2:$I$37,$B$2:$B$37,B3) -> 0.94339623 | K3: =IF(F3="Jalon",INDEX(Hypotheses!$C$6:$C$12,MATCH(A3,Hypotheses!$A$6:$A$12,0)),K2+I3*J3) -> 66478.302 | L3: =IF(F3="Jalon","Point de repère fixé au TP1 (jalon) — valeur non recalculée","Indice "&TEXT(H3,"+0%;-0%;0%")&" en "&E3&" : "&INDEX(Hypotheses!$D$65:$D$76,MATCH(D3,Hypotheses!$B$65:$B$76,0))) -> Indice +25% en Décembre : Forte hausse des achats alimentaires liée aux fêtes de fin d'année
A4: 3 | B4: =MATCH(A4-1,Hypotheses!$A$6:$A$12,1) -> 1 | C4: =Hypotheses!$B$62+INT((Hypotheses!$B$61-1+(A4-1))/12) -> 2027 | D4: =MOD(Hypotheses!$B$61-1+(A4-1),12)+1 -> 1 | E4: =CHOOSE(D4,"Janvier","Février","Mars","Avril","Mai","Juin","Juillet","Août","Septembre","Octobre","Novembre","Décembre") -> Janvier | F4: =IF(COUNTIF(Hypotheses!$A$6:$A$12,A4)>0,"Jalon","Interpolé") -> Interpolé | G4: =(INDEX(Hypotheses!$C$6:$C$12,B4+1)-INDEX(Hypotheses!$C$6:$C$12,B4))/(INDEX(Hypotheses!$A$6:$A$12,B4+1)-INDEX(Hypotheses!$A$6:$A$12,B4)) -> 43060 | H4: =INDEX(Hypotheses!$C$65:$C$76,MATCH(D4,Hypotheses!$B$65:$B$76,0)) -> 0.1 | I4: =G4*(1+H4) -> 47366 | J4: =(INDEX(Hypotheses!$C$6:$C$12,B4+1)-INDEX(Hypotheses!$C$6:$C$12,B4))/SUMIFS($I$2:$I$37,$B$2:$B$37,B4) -> 0.94339623 | K4: =IF(F4="Jalon",INDEX(Hypotheses!$C$6:$C$12,MATCH(A4,Hypotheses!$A$6:$A$12,0)),K3+I4*J4) -> 111163.21 | L4: =IF(F4="Jalon","Point de repère fixé au TP1 (jalon) — valeur non recalculée","Indice "&TEXT(H4,"+0%;-0%;0%")&" en "&E4&" : "&INDEX(Hypotheses!$D$65:$D$76,MATCH(D4,Hypotheses!$B$65:$B$76,0))) -> Indice +10% en Janvier : Hausse liée aux régimes et à la remise en forme après les fêtes
A5: 4 | B5: =MATCH(A5-1,Hypotheses!$A$6:$A$12,1) -> 1 | C5: =Hypotheses!$B$62+INT((Hypotheses!$B$61-1+(A5-1))/12) -> 2027 | D5: =MOD(Hypotheses!$B$61-1+(A5-1),12)+1 -> 2 | E5: =CHOOSE(D5,"Janvier","Février","Mars","Avril","Mai","Juin","Juillet","Août","Septembre","Octobre","Novembre","Décembre") -> Février | F5: =IF(COUNTIF(Hypotheses!$A$6:$A$12,A5)>0,"Jalon","Interpolé") -> Interpolé | G5: =(INDEX(Hypotheses!$C$6:$C$12,B5+1)-INDEX(Hypotheses!$C$6:$C$12,B5))/(INDEX(Hypotheses!$A$6:$A$12,B5+1)-INDEX(Hypotheses!$A$6:$A$12,B5)) -> 43060 | H5: =INDEX(Hypotheses!$C$65:$C$76,MATCH(D5,Hypotheses!$B$65:$B$76,0)) -> -0.05 | I5: =G5*(1+H5) -> 40907 | J5: =(INDEX(Hypotheses!$C$6:$C$12,B5+1)-INDEX(Hypotheses!$C$6:$C$12,B5))/SUMIFS($I$2:$I$37,$B$2:$B$37,B5) -> 0.94339623 | K5: =IF(F5="Jalon",INDEX(Hypotheses!$C$6:$C$12,MATCH(A5,Hypotheses!$A$6:$A$12,0)),K4+I5*J5) -> 149754.72 | L5: =IF(F5="Jalon","Point de repère fixé au TP1 (jalon) — valeur non recalculée","Indice "&TEXT(H5,"+0%;-0%;0%")&" en "&E5&" : "&INDEX(Hypotheses!$D$65:$D$76,MATCH(D5,Hypotheses!$B$65:$B$76,0))) -> Indice -5% en Février : Consommation en retrait, creux hors période de fêtes
A6: 5 | B6: =MATCH(A6-1,Hypotheses!$A$6:$A$12,1) -> 1 | C6: =Hypotheses!$B$62+INT((Hypotheses!$B$61-1+(A6-1))/12) -> 2027 | D6: =MOD(Hypotheses!$B$61-1+(A6-1),12)+1 -> 3 | E6: =CHOOSE(D6,"Janvier","Février","Mars","Avril","Mai","Juin","Juillet","Août","Septembre","Octobre","Novembre","Décembre") -> Mars | F6: =IF(COUNTIF(Hypotheses!$A$6:$A$12,A6)>0,"Jalon","Interpolé") -> Interpolé | G6: =(INDEX(Hypotheses!$C$6:$C$12,B6+1)-INDEX(Hypotheses!$C$6:$C$12,B6))/(INDEX(Hypotheses!$A$6:$A$12,B6+1)-INDEX(Hypotheses!$A$6:$A$12,B6)) -> 43060 | H6: =INDEX(Hypotheses!$C$65:$C$76,MATCH(D6,Hypotheses!$B$65:$B$76,0)) -> -0.05 | I6: =G6*(1+H6) -> 40907 | J6: =(INDEX(Hypotheses!$C$6:$C$12,B6+1)-INDEX(Hypotheses!$C$6:$C$12,B6))/SUMIFS($I$2:$I$37,$B$2:$B$37,B6) -> 0.94339623 | K6: =IF(F6="Jalon",INDEX(Hypotheses!$C$6:$C$12,MATCH(A6,Hypotheses!$A$6:$A$12,0)),K5+I6*J6) -> 188346.23 | L6: =IF(F6="Jalon","Point de repère fixé au TP1 (jalon) — valeur non recalculée","Indice "&TEXT(H6,"+0%;-0%;0%")&" en "&E6&" : "&INDEX(Hypotheses!$D$65:$D$76,MATCH(D6,Hypotheses!$B$65:$B$76,0))) -> Indice -5% en Mars : Consommation en retrait, avant la reprise liée à Pâques
A7: 6 | B7: =MATCH(A7-1,Hypotheses!$A$6:$A$12,1) -> 1 | C7: =Hypotheses!$B$62+INT((Hypotheses!$B$61-1+(A7-1))/12) -> 2027 | D7: =MOD(Hypotheses!$B$61-1+(A7-1),12)+1 -> 4 | E7: =CHOOSE(D7,"Janvier","Février","Mars","Avril","Mai","Juin","Juillet","Août","Septembre","Octobre","Novembre","Décembre") -> Avril | F7: =IF(COUNTIF(Hypotheses!$A$6:$A$12,A7)>0,"Jalon","Interpolé") -> Jalon | G7: =(INDEX(Hypotheses!$C$6:$C$12,B7+1)-INDEX(Hypotheses!$C$6:$C$12,B7))/(INDEX(Hypotheses!$A$6:$A$12,B7+1)-INDEX(Hypotheses!$A$6:$A$12,B7)) -> 43060 | H7: =INDEX(Hypotheses!$C$65:$C$76,MATCH(D7,Hypotheses!$B$65:$B$76,0)) -> 0.05 | I7: =G7*(1+H7) -> 45213 | J7: =(INDEX(Hypotheses!$C$6:$C$12,B7+1)-INDEX(Hypotheses!$C$6:$C$12,B7))/SUMIFS($I$2:$I$37,$B$2:$B$37,B7) -> 0.94339623 | K7: =IF(F7="Jalon",INDEX(Hypotheses!$C$6:$C$12,MATCH(A7,Hypotheses!$A$6:$A$12,0)),K6+I7*J7) -> 231000 | L7: =IF(F7="Jalon","Point de repère fixé au TP1 (jalon) — valeur non recalculée","Indice "&TEXT(H7,"+0%;-0%;0%")&" en "&E7&" : "&INDEX(Hypotheses!$D$65:$D$76,MATCH(D7,Hypotheses!$B$65:$B$76,0))) -> Point de repère fixé au TP1 (jalon) — valeur non recalculée
A8: 7 | B8: =MATCH(A8-1,Hypotheses!$A$6:$A$12,1) -> 2 | C8: =Hypotheses!$B$62+INT((Hypotheses!$B$61-1+(A8-1))/12) -> 2027 | D8: =MOD(Hypotheses!$B$61-1+(A8-1),12)+1 -> 5 | E8: =CHOOSE(D8,"Janvier","Février","Mars","Avril","Mai","Juin","Juillet","Août","Septembre","Octobre","Novembre","Décembre") -> Mai | F8: =IF(COUNTIF(Hypotheses!$A$6:$A$12,A8)>0,"Jalon","Interpolé") -> Interpolé | G8: =(INDEX(Hypotheses!$C$6:$C$12,B8+1)-INDEX(Hypotheses!$C$6:$C$12,B8))/(INDEX(Hypotheses!$A$6:$A$12,B8+1)-INDEX(Hypotheses!$A$6:$A$12,B8)) -> 70500 | H8: =INDEX(Hypotheses!$C$65:$C$76,MATCH(D8,Hypotheses!$B$65:$B$76,0)) -> 0.05 | I8: =G8*(1+H8) -> 74025 | J8: =(INDEX(Hypotheses!$C$6:$C$12,B8+1)-INDEX(Hypotheses!$C$6:$C$12,B8))/SUMIFS($I$2:$I$37,$B$2:$B$37,B8) -> 0.95238095 | K8: =IF(F8="Jalon",INDEX(Hypotheses!$C$6:$C$12,MATCH(A8,Hypotheses!$A$6:$A$12,0)),K7+I8*J8) -> 301500 | L8: =IF(F8="Jalon","Point de repère fixé au TP1 (jalon) — valeur non recalculée","Indice "&TEXT(H8,"+0%;-0%;0%")&" en "&E8&" : "&INDEX(Hypotheses!$D$65:$D$76,MATCH(D8,Hypotheses!$B$65:$B$76,0))) -> Indice +5% en Mai : Consommation légèrement supérieure à la moyenne annuelle
A9: 8 | B9: =MATCH(A9-1,Hypotheses!$A$6:$A$12,1) -> 2 | C9: =Hypotheses!$B$62+INT((Hypotheses!$B$61-1+(A9-1))/12) -> 2027 | D9: =MOD(Hypotheses!$B$61-1+(A9-1),12)+1 -> 6 | E9: =CHOOSE(D9,"Janvier","Février","Mars","Avril","Mai","Juin","Juillet","Août","Septembre","Octobre","Novembre","Décembre") -> Juin | F9: =IF(COUNTIF(Hypotheses!$A$6:$A$12,A9)>0,"Jalon","Interpolé") -> Interpolé | G9: =(INDEX(Hypotheses!$C$6:$C$12,B9+1)-INDEX(Hypotheses!$C$6:$C$12,B9))/(INDEX(Hypotheses!$A$6:$A$12,B9+1)-INDEX(Hypotheses!$A$6:$A$12,B9)) -> 70500 | H9: =INDEX(Hypotheses!$C$65:$C$76,MATCH(D9,Hypotheses!$B$65:$B$76,0)) -> 0 | I9: =G9*(1+H9) -> 70500 | J9: =(INDEX(Hypotheses!$C$6:$C$12,B9+1)-INDEX(Hypotheses!$C$6:$C$12,B9))/SUMIFS($I$2:$I$37,$B$2:$B$37,B9) -> 0.95238095 | K9: =IF(F9="Jalon",INDEX(Hypotheses!$C$6:$C$12,MATCH(A9,Hypotheses!$A$6:$A$12,0)),K8+I9*J9) -> 368642.86 | L9: =IF(F9="Jalon","Point de repère fixé au TP1 (jalon) — valeur non recalculée","Indice "&TEXT(H9,"+0%;-0%;0%")&" en "&E9&" : "&INDEX(Hypotheses!$D$65:$D$76,MATCH(D9,Hypotheses!$B$65:$B$76,0))) -> Indice 0% en Juin : Mois de référence (indice 100)
A10: 9 | B10: =MATCH(A10-1,Hypotheses!$A$6:$A$12,1) -> 2 | C10: =Hypotheses!$B$62+INT((Hypotheses!$B$61-1+(A10-1))/12) -> 2027 | D10: =MOD(Hypotheses!$B$61-1+(A10-1),12)+1 -> 7 | E10: =CHOOSE(D10,"Janvier","Février","Mars","Avril","Mai","Juin","Juillet","Août","Septembre","Octobre","Novembre","Décembre") -> Juillet | F10: =IF(COUNTIF(Hypotheses!$A$6:$A$12,A10)>0,"Jalon","Interpolé") -> Interpolé | G10: =(INDEX(Hypotheses!$C$6:$C$12,B10+1)-INDEX(Hypotheses!$C$6:$C$12,B10))/(INDEX(Hypotheses!$A$6:$A$12,B10+1)-INDEX(Hypotheses!$A$6:$A$12,B10)) -> 70500 | H10: =INDEX(Hypotheses!$C$65:$C$76,MATCH(D10,Hypotheses!$B$65:$B$76,0)) -> 0.15 | I10: =G10*(1+H10) -> 81075 | J10: =(INDEX(Hypotheses!$C$6:$C$12,B10+1)-INDEX(Hypotheses!$C$6:$C$12,B10))/SUMIFS($I$2:$I$37,$B$2:$B$37,B10) -> 0.95238095 | K10: =IF(F10="Jalon",INDEX(Hypotheses!$C$6:$C$12,MATCH(A10,Hypotheses!$A$6:$A$12,0)),K9+I10*J10) -> 445857.14 | L10: =IF(F10="Jalon","Point de repère fixé au TP1 (jalon) — valeur non recalculée","Indice "&TEXT(H10,"+0%;-0%;0%")&" en "&E10&" : "&INDEX(Hypotheses!$D$65:$D$76,MATCH(D10,Hypotheses!$B$65:$B$76,0))) -> Indice +15% en Juillet : Hausse des boissons, glaces et produits d'extérieur (grillades, pique-nique)
A11: 10 | B11: =MATCH(A11-1,Hypotheses!$A$6:$A$12,1) -> 2 | C11: =Hypotheses!$B$62+INT((Hypotheses!$B$61-1+(A11-1))/12) -> 2027 | D11: =MOD(Hypotheses!$B$61-1+(A11-1),12)+1 -> 8 | E11: =CHOOSE(D11,"Janvier","Février","Mars","Avril","Mai","Juin","Juillet","Août","Septembre","Octobre","Novembre","Décembre") -> Août | F11: =IF(COUNTIF(Hypotheses!$A$6:$A$12,A11)>0,"Jalon","Interpolé") -> Interpolé | G11: =(INDEX(Hypotheses!$C$6:$C$12,B11+1)-INDEX(Hypotheses!$C$6:$C$12,B11))/(INDEX(Hypotheses!$A$6:$A$12,B11+1)-INDEX(Hypotheses!$A$6:$A$12,B11)) -> 70500 | H11: =INDEX(Hypotheses!$C$65:$C$76,MATCH(D11,Hypotheses!$B$65:$B$76,0)) -> 0.15 | I11: =G11*(1+H11) -> 81075 | J11: =(INDEX(Hypotheses!$C$6:$C$12,B11+1)-INDEX(Hypotheses!$C$6:$C$12,B11))/SUMIFS($I$2:$I$37,$B$2:$B$37,B11) -> 0.95238095 | K11: =IF(F11="Jalon",INDEX(Hypotheses!$C$6:$C$12,MATCH(A11,Hypotheses!$A$6:$A$12,0)),K10+I11*J11) -> 523071.43 | L11: =IF(F11="Jalon","Point de repère fixé au TP1 (jalon) — valeur non recalculée","Indice "&TEXT(H11,"+0%;-0%;0%")&" en "&E11&" : "&INDEX(Hypotheses!$D$65:$D$76,MATCH(D11,Hypotheses!$B$65:$B$76,0))) -> Indice +15% en Août : Cœur des vacances d'été : boissons, glaces, produits d'extérieur
A12: 11 | B12: =MATCH(A12-1,Hypotheses!$A$6:$A$12,1) -> 2 | C12: =Hypotheses!$B$62+INT((Hypotheses!$B$61-1+(A12-1))/12) -> 2027 | D12: =MOD(Hypotheses!$B$61-1+(A12-1),12)+1 -> 9 | E12: =CHOOSE(D12,"Janvier","Février","Mars","Avril","Mai","Juin","Juillet","Août","Septembre","Octobre","Novembre","Décembre") -> Septembre | F12: =IF(COUNTIF(Hypotheses!$A$6:$A$12,A12)>0,"Jalon","Interpolé") -> Interpolé | G12: =(INDEX(Hypotheses!$C$6:$C$12,B12+1)-INDEX(Hypotheses!$C$6:$C$12,B12))/(INDEX(Hypotheses!$A$6:$A$12,B12+1)-INDEX(Hypotheses!$A$6:$A$12,B12)) -> 70500 | H12: =INDEX(Hypotheses!$C$65:$C$76,MATCH(D12,Hypotheses!$B$65:$B$76,0)) -> -0.05 | I12: =G12*(1+H12) -> 66975 | J12: =(INDEX(Hypotheses!$C$6:$C$12,B12+1)-INDEX(Hypotheses!$C$6:$C$12,B12))/SUMIFS($I$2:$I$37,$B$2:$B$37,B12) -> 0.95238095 | K12: =IF(F12="Jalon",INDEX(Hypotheses!$C$6:$C$12,MATCH(A12,Hypotheses!$A$6:$A$12,0)),K11+I12*J12) -> 586857.14 | L12: =IF(F12="Jalon","Point de repère fixé au TP1 (jalon) — valeur non recalculée","Indice "&TEXT(H12,"+0%;-0%;0%")&" en "&E12&" : "&INDEX(Hypotheses!$D$65:$D$76,MATCH(D12,Hypotheses!$B$65:$B$76,0))) -> Indice -5% en Septembre : Rentrée : consommation en retrait par rapport à la moyenne annuelle
A13: 12 | B13: =MATCH(A13-1,Hypotheses!$A$6:$A$12,1) -> 2 | C13: =Hypotheses!$B$62+INT((Hypotheses!$B$61-1+(A13-1))/12) -> 2027 | D13: =MOD(Hypotheses!$B$61-1+(A13-1),12)+1 -> 10 | E13: =CHOOSE(D13,"Janvier","Février","Mars","Avril","Mai","Juin","Juillet","Août","Septembre","Octobre","Novembre","Décembre") -> Octobre | F13: =IF(COUNTIF(Hypotheses!$A$6:$A$12,A13)>0,"Jalon","Interpolé") -> Jalon | G13: =(INDEX(Hypotheses!$C$6:$C$12,B13+1)-INDEX(Hypotheses!$C$6:$C$12,B13))/(INDEX(Hypotheses!$A$6:$A$12,B13+1)-INDEX(Hypotheses!$A$6:$A$12,B13)) -> 70500 | H13: =INDEX(Hypotheses!$C$65:$C$76,MATCH(D13,Hypotheses!$B$65:$B$76,0)) -> 0 | I13: =G13*(1+H13) -> 70500 | J13: =(INDEX(Hypotheses!$C$6:$C$12,B13+1)-INDEX(Hypotheses!$C$6:$C$12,B13))/SUMIFS($I$2:$I$37,$B$2:$B$37,B13) -> 0.95238095 | K13: =IF(F13="Jalon",INDEX(Hypotheses!$C$6:$C$12,MATCH(A13,Hypotheses!$A$6:$A$12,0)),K12+I13*J13) -> 654000 | L13: =IF(F13="Jalon","Point de repère fixé au TP1 (jalon) — valeur non recalculée","Indice "&TEXT(H13,"+0%;-0%;0%")&" en "&E13&" : "&INDEX(Hypotheses!$D$65:$D$76,MATCH(D13,Hypotheses!$B$65:$B$76,0))) -> Point de repère fixé au TP1 (jalon) — valeur non recalculée
A14: 13 | B14: =MATCH(A14-1,Hypotheses!$A$6:$A$12,1) -> 3 | C14: =Hypotheses!$B$62+INT((Hypotheses!$B$61-1+(A14-1))/12) -> 2027 | D14: =MOD(Hypotheses!$B$61-1+(A14-1),12)+1 -> 11 | E14: =CHOOSE(D14,"Janvier","Février","Mars","Avril","Mai","Juin","Juillet","Août","Septembre","Octobre","Novembre","Décembre") -> Novembre | F14: =IF(COUNTIF(Hypotheses!$A$6:$A$12,A14)>0,"Jalon","Interpolé") -> Interpolé | G14: =(INDEX(Hypotheses!$C$6:$C$12,B14+1)-INDEX(Hypotheses!$C$6:$C$12,B14))/(INDEX(Hypotheses!$A$6:$A$12,B14+1)-INDEX(Hypotheses!$A$6:$A$12,B14)) -> 91333.333 | H14: =INDEX(Hypotheses!$C$65:$C$76,MATCH(D14,Hypotheses!$B$65:$B$76,0)) -> 0 | I14: =G14*(1+H14) -> 91333.333 | J14: =(INDEX(Hypotheses!$C$6:$C$12,B14+1)-INDEX(Hypotheses!$C$6:$C$12,B14))/SUMIFS($I$2:$I$37,$B$2:$B$37,B14) -> 0.95238095 | K14: =IF(F14="Jalon",INDEX(Hypotheses!$C$6:$C$12,MATCH(A14,Hypotheses!$A$6:$A$12,0)),K13+I14*J14) -> 740984.13 | L14: =IF(F14="Jalon","Point de repère fixé au TP1 (jalon) — valeur non recalculée","Indice "&TEXT(H14,"+0%;-0%;0%")&" en "&E14&" : "&INDEX(Hypotheses!$D$65:$D$76,MATCH(D14,Hypotheses!$B$65:$B$76,0))) -> Indice 0% en Novembre : Mois de référence (indice 100)
... A37: 36 | B37: =MATCH(A37-1,Hypotheses!$A$6:$A$12,1) -> 6 | C37: =Hypotheses!$B$62+INT((Hypotheses!$B$61-1+(A37-1))/12) -> 2029 | D37: =MOD(Hypotheses!$B$61-1+(A37-1),12)+1 -> 10 | E37: =CHOOSE(D37,"Janvier","Février","Mars","Avril","Mai","Juin","Juillet","Août","Septembre","Octobre","Novembre","Décembre") -> Octobre | F37: =IF(COUNTIF(Hypotheses!$A$6:$A$12,A37)>0,"Jalon","Interpolé") -> Jalon | G37: =(INDEX(Hypotheses!$C$6:$C$12,B37+1)-INDEX(Hypotheses!$C$6:$C$12,B37))/(INDEX(Hypotheses!$A$6:$A$12,B37+1)-INDEX(Hypotheses!$A$6:$A$12,B37)) -> 135666.67 | H37: =INDEX(Hypotheses!$C$65:$C$76,MATCH(D37,Hypotheses!$B$65:$B$76,0)) -> 0 | I37: =G37*(1+H37) -> 135666.67 | J37: =(INDEX(Hypotheses!$C$6:$C$12,B37+1)-INDEX(Hypotheses!$C$6:$C$12,B37))/SUMIFS($I$2:$I$37,$B$2:$B$37,B37) -> 0.95238095 | K37: =IF(F37="Jalon",INDEX(Hypotheses!$C$6:$C$12,MATCH(A37,Hypotheses!$A$6:$A$12,0)),K36+I37*J37) -> 3400000 | L37: =IF(F37="Jalon","Point de repère fixé au TP1 (jalon) — valeur non recalculée","Indice "&TEXT(H37,"+0%;-0%;0%")&" en "&E37&" : "&INDEX(Hypotheses!$D$65:$D$76,MATCH(D37,Hypotheses!$B$65:$B$76,0))) -> Point de repère fixé au TP1 (jalon) — valeur non recalculée

Sheet Couts
A1: Mois | B1: Build - Équipe & données | C1: Build - Briques complémentaires | D1: Run - Hébergement | E1: Run - LLM (assistant) | F1: Run - Stockage | G1: Run - Supervision | H1: Run - Journalisation & surveillance | I1: Change - Acquisition | J1: Change - Accompagnement | K1: Conformité | L1: Total mensuel | M1: Cumul
A2: 1 | B2: =IF($A2=1,Hypotheses!$B$32,0)+IF($A2<=Hypotheses!$B$28,Hypotheses!$B$29/Hypotheses!$B$28,0) -> 29500 | C2: =IF($A2<=Hypotheses!$B$28,Hypotheses!$B$88/Hypotheses!$B$28,0) -> 2785.7143 | D2: =MAU_mensuel!$K2*Hypotheses!$B$36/12 -> 157 | E2: =MAU_mensuel!$K2*Hypotheses!$B$38*Hypotheses!$B$39*Hypotheses!$B$40*Hypotheses!$B$41/1000000 -> 37.68 | F2: =MAU_mensuel!$K2*Hypotheses!$B$37/12 -> 19.625 | G2: =Hypotheses!$B$43/12 -> 1450 | H2: =MAU_mensuel!$K2*Hypotheses!$B$89/12 -> 13.083333 | I2: =Hypotheses!$B$46/12 -> 3333.3333 | J2: =Hypotheses!$B$47/12 -> 666.66667 | K2: =Hypotheses!$B$51/12 -> 500 | L2: =SUM(B2:K2) -> 38463.103 | M2: =L2 -> 38463.103
A3: 2 | B3: =IF($A3=1,Hypotheses!$B$32,0)+IF($A3<=Hypotheses!$B$28,Hypotheses!$B$29/Hypotheses!$B$28,0) -> 14500 | C3: =IF($A3<=Hypotheses!$B$28,Hypotheses!$B$88/Hypotheses!$B$28,0) -> 2785.7143 | D3: =MAU_mensuel!$K3*Hypotheses!$B$36/12 -> 664.78302 | E3: =MAU_mensuel!$K3*Hypotheses!$B$38*Hypotheses!$B$39*Hypotheses!$B$40*Hypotheses!$B$41/1000000 -> 159.54792 | F3: =MAU_mensuel!$K3*Hypotheses!$B$37/12 -> 83.097877 | G3: =Hypotheses!$B$43/12 -> 1450 | H3: =MAU_mensuel!$K3*Hypotheses!$B$89/12 -> 55.398585 | I3: =Hypotheses!$B$46/12 -> 3333.3333 | J3: =Hypotheses!$B$47/12 -> 666.66667 | K3: =Hypotheses!$B$51/12 -> 500 | L3: =SUM(B3:K3) -> 24198.542 | M3: =M2+L3 -> 62661.644
A4: 3 | B4: =IF($A4=1,Hypotheses!$B$32,0)+IF($A4<=Hypotheses!$B$28,Hypotheses!$B$29/Hypotheses!$B$28,0) -> 14500 | C4: =IF($A4<=Hypotheses!$B$28,Hypotheses!$B$88/Hypotheses!$B$28,0) -> 2785.7143 | D4: =MAU_mensuel!$K4*Hypotheses!$B$36/12 -> 1111.6321 | E4: =MAU_mensuel!$K4*Hypotheses!$B$38*Hypotheses!$B$39*Hypotheses!$B$40*Hypotheses!$B$41/1000000 -> 266.7917 | F4: =MAU_mensuel!$K4*Hypotheses!$B$37/12 -> 138.95401 | G4: =Hypotheses!$B$43/12 -> 1450 | H4: =MAU_mensuel!$K4*Hypotheses!$B$89/12 -> 92.636006 | I4: =Hypotheses!$B$46/12 -> 3333.3333 | J4: =Hypotheses!$B$47/12 -> 666.66667 | K4: =Hypotheses!$B$51/12 -> 500 | L4: =SUM(B4:K4) -> 24845.728 | M4: =M3+L4 -> 87507.372
A5: 4 | B5: =IF($A5=1,Hypotheses!$B$32,0)+IF($A5<=Hypotheses!$B$28,Hypotheses!$B$29/Hypotheses!$B$28,0) -> 14500 | C5: =IF($A5<=Hypotheses!$B$28,Hypotheses!$B$88/Hypotheses!$B$28,0) -> 2785.7143 | D5: =MAU_mensuel!$K5*Hypotheses!$B$36/12 -> 1497.5472 | E5: =MAU_mensuel!$K5*Hypotheses!$B$38*Hypotheses!$B$39*Hypotheses!$B$40*Hypotheses!$B$41/1000000 -> 359.41132 | F5: =MAU_mensuel!$K5*Hypotheses!$B$37/12 -> 187.1934 | G5: =Hypotheses!$B$43/12 -> 1450 | H5: =MAU_mensuel!$K5*Hypotheses!$B$89/12 -> 124.7956 | I5: =Hypotheses!$B$46/12 -> 3333.3333 | J5: =Hypotheses!$B$47/12 -> 666.66667 | K5: =Hypotheses!$B$51/12 -> 500 | L5: =SUM(B5:K5) -> 25404.662 | M5: =M4+L5 -> 112912.03
A6: 5 | B6: =IF($A6=1,Hypotheses!$B$32,0)+IF($A6<=Hypotheses!$B$28,Hypotheses!$B$29/Hypotheses!$B$28,0) -> 14500 | C6: =IF($A6<=Hypotheses!$B$28,Hypotheses!$B$88/Hypotheses!$B$28,0) -> 2785.7143 | D6: =MAU_mensuel!$K6*Hypotheses!$B$36/12 -> 1883.4623 | E6: =MAU_mensuel!$K6*Hypotheses!$B$38*Hypotheses!$B$39*Hypotheses!$B$40*Hypotheses!$B$41/1000000 -> 452.03094 | F6: =MAU_mensuel!$K6*Hypotheses!$B$37/12 -> 235.43278 | G6: =Hypotheses!$B$43/12 -> 1450 | H6: =MAU_mensuel!$K6*Hypotheses!$B$89/12 -> 156.95519 | I6: =Hypotheses!$B$46/12 -> 3333.3333 | J6: =Hypotheses!$B$47/12 -> 666.66667 | K6: =Hypotheses!$B$51/12 -> 500 | L6: =SUM(B6:K6) -> 25963.595 | M6: =M5+L6 -> 138875.63
A7: 6 | B7: =IF($A7=1,Hypotheses!$B$32,0)+IF($A7<=Hypotheses!$B$28,Hypotheses!$B$29/Hypotheses!$B$28,0) -> 14500 | C7: =IF($A7<=Hypotheses!$B$28,Hypotheses!$B$88/Hypotheses!$B$28,0) -> 2785.7143 | D7: =MAU_mensuel!$K7*Hypotheses!$B$36/12 -> 2310 | E7: =MAU_mensuel!$K7*Hypotheses!$B$38*Hypotheses!$B$39*Hypotheses!$B$40*Hypotheses!$B$41/1000000 -> 554.4 | F7: =MAU_mensuel!$K7*Hypotheses!$B$37/12 -> 288.75 | G7: =Hypotheses!$B$43/12 -> 1450 | H7: =MAU_mensuel!$K7*Hypotheses!$B$89/12 -> 192.5 | I7: =Hypotheses!$B$46/12 -> 3333.3333 | J7: =Hypotheses!$B$47/12 -> 666.66667 | K7: =Hypotheses!$B$51/12 -> 500 | L7: =SUM(B7:K7) -> 26581.364 | M7: =M6+L7 -> 165456.99
A8: 7 | B8: =IF($A8=1,Hypotheses!$B$32,0)+IF($A8<=Hypotheses!$B$28,Hypotheses!$B$29/Hypotheses!$B$28,0) -> 14500 | C8: =IF($A8<=Hypotheses!$B$28,Hypotheses!$B$88/Hypotheses!$B$28,0) -> 2785.7143 | D8: =MAU_mensuel!$K8*Hypotheses!$B$36/12 -> 3015 | E8: =MAU_mensuel!$K8*Hypotheses!$B$38*Hypotheses!$B$39*Hypotheses!$B$40*Hypotheses!$B$41/1000000 -> 723.6 | F8: =MAU_mensuel!$K8*Hypotheses!$B$37/12 -> 376.875 | G8: =Hypotheses!$B$43/12 -> 1450 | H8: =MAU_mensuel!$K8*Hypotheses!$B$89/12 -> 251.25 | I8: =Hypotheses!$B$46/12 -> 3333.3333 | J8: =Hypotheses!$B$47/12 -> 666.66667 | K8: =Hypotheses!$B$51/12 -> 500 | L8: =SUM(B8:K8) -> 27602.439 | M8: =M7+L8 -> 193059.43
A9: 8 | B9: =IF($A9=1,Hypotheses!$B$32,0)+IF($A9<=Hypotheses!$B$28,Hypotheses!$B$29/Hypotheses!$B$28,0) -> 0 | C9: =IF($A9<=Hypotheses!$B$28,Hypotheses!$B$88/Hypotheses!$B$28,0) -> 0 | D9: =MAU_mensuel!$K9*Hypotheses!$B$36/12 -> 3686.4286 | E9: =MAU_mensuel!$K9*Hypotheses!$B$38*Hypotheses!$B$39*Hypotheses!$B$40*Hypotheses!$B$41/1000000 -> 884.74286 | F9: =MAU_mensuel!$K9*Hypotheses!$B$37/12 -> 460.80357 | G9: =Hypotheses!$B$43/12 -> 1450 | H9: =MAU_mensuel!$K9*Hypotheses!$B$89/12 -> 307.20238 | I9: =Hypotheses!$B$46/12 -> 3333.3333 | J9: =Hypotheses!$B$47/12 -> 666.66667 | K9: =Hypotheses!$B$51/12 -> 500 | L9: =SUM(B9:K9) -> 11289.177 | M9: =M8+L9 -> 204348.61
A10: 9 | B10: =IF($A10=1,Hypotheses!$B$32,0)+IF($A10<=Hypotheses!$B$28,Hypotheses!$B$29/Hypotheses!$B$28,0) -> 0 | C10: =IF($A10<=Hypotheses!$B$28,Hypotheses!$B$88/Hypotheses!$B$28,0) -> 0 | D10: =MAU_mensuel!$K10*Hypotheses!$B$36/12 -> 4458.5714 | E10: =MAU_mensuel!$K10*Hypotheses!$B$38*Hypotheses!$B$39*Hypotheses!$B$40*Hypotheses!$B$41/1000000 -> 1070.0571 | F10: =MAU_mensuel!$K10*Hypotheses!$B$37/12 -> 557.32143 | G10: =Hypotheses!$B$43/12 -> 1450 | H10: =MAU_mensuel!$K10*Hypotheses!$B$89/12 -> 371.54762 | I10: =Hypotheses!$B$46/12 -> 3333.3333 | J10: =Hypotheses!$B$47/12 -> 666.66667 | K10: =Hypotheses!$B$51/12 -> 500 | L10: =SUM(B10:K10) -> 12407.498 | M10: =M9+L10 -> 216756.11
A11: 10 | B11: =IF($A11=1,Hypotheses!$B$32,0)+IF($A11<=Hypotheses!$B$28,Hypotheses!$B$29/Hypotheses!$B$28,0) -> 0 | C11: =IF($A11<=Hypotheses!$B$28,Hypotheses!$B$88/Hypotheses!$B$28,0) -> 0 | D11: =MAU_mensuel!$K11*Hypotheses!$B$36/12 -> 5230.7143 | E11: =MAU_mensuel!$K11*Hypotheses!$B$38*Hypotheses!$B$39*Hypotheses!$B$40*Hypotheses!$B$41/1000000 -> 1255.3714 | F11: =MAU_mensuel!$K11*Hypotheses!$B$37/12 -> 653.83929 | G11: =Hypotheses!$B$43/12 -> 1450 | H11: =MAU_mensuel!$K11*Hypotheses!$B$89/12 -> 435.89286 | I11: =Hypotheses!$B$46/12 -> 3333.3333 | J11: =Hypotheses!$B$47/12 -> 666.66667 | K11: =Hypotheses!$B$51/12 -> 500 | L11: =SUM(B11:K11) -> 13525.818 | M11: =M10+L11 -> 230281.93
A12: 11 | B12: =IF($A12=1,Hypotheses!$B$32,0)+IF($A12<=Hypotheses!$B$28,Hypotheses!$B$29/Hypotheses!$B$28,0) -> 0 | C12: =IF($A12<=Hypotheses!$B$28,Hypotheses!$B$88/Hypotheses!$B$28,0) -> 0 | D12: =MAU_mensuel!$K12*Hypotheses!$B$36/12 -> 5868.5714 | E12: =MAU_mensuel!$K12*Hypotheses!$B$38*Hypotheses!$B$39*Hypotheses!$B$40*Hypotheses!$B$41/1000000 -> 1408.4571 | F12: =MAU_mensuel!$K12*Hypotheses!$B$37/12 -> 733.57143 | G12: =Hypotheses!$B$43/12 -> 1450 | H12: =MAU_mensuel!$K12*Hypotheses!$B$89/12 -> 489.04762 | I12: =Hypotheses!$B$46/12 -> 3333.3333 | J12: =Hypotheses!$B$47/12 -> 666.66667 | K12: =Hypotheses!$B$51/12 -> 500 | L12: =SUM(B12:K12) -> 14449.648 | M12: =M11+L12 -> 244731.57
A13: 12 | B13: =IF($A13=1,Hypotheses!$B$32,0)+IF($A13<=Hypotheses!$B$28,Hypotheses!$B$29/Hypotheses!$B$28,0) -> 0 | C13: =IF($A13<=Hypotheses!$B$28,Hypotheses!$B$88/Hypotheses!$B$28,0) -> 0 | D13: =MAU_mensuel!$K13*Hypotheses!$B$36/12 -> 6540 | E13: =MAU_mensuel!$K13*Hypotheses!$B$38*Hypotheses!$B$39*Hypotheses!$B$40*Hypotheses!$B$41/1000000 -> 1569.6 | F13: =MAU_mensuel!$K13*Hypotheses!$B$37/12 -> 817.5 | G13: =Hypotheses!$B$43/12 -> 1450 | H13: =MAU_mensuel!$K13*Hypotheses!$B$89/12 -> 545 | I13: =Hypotheses!$B$46/12 -> 3333.3333 | J13: =Hypotheses!$B$47/12 -> 666.66667 | K13: =Hypotheses!$B$51/12 -> 500 | L13: =SUM(B13:K13) -> 15422.1 | M13: =M12+L13 -> 260153.67
A14: 13 | B14: =IF($A14=1,Hypotheses!$B$32,0)+IF($A14<=Hypotheses!$B$28,Hypotheses!$B$29/Hypotheses!$B$28,0) -> 0 | C14: =IF($A14<=Hypotheses!$B$28,Hypotheses!$B$88/Hypotheses!$B$28,0) -> 0 | D14: =MAU_mensuel!$K14*Hypotheses!$B$36/12 -> 7409.8413 | E14: =MAU_mensuel!$K14*Hypotheses!$B$38*Hypotheses!$B$39*Hypotheses!$B$40*Hypotheses!$B$41/1000000 -> 1778.3619 | F14: =MAU_mensuel!$K14*Hypotheses!$B$37/12 -> 926.23016 | G14: =Hypotheses!$B$43/12 -> 1450 | H14: =MAU_mensuel!$K14*Hypotheses!$B$89/12 -> 617.48677 | I14: =Hypotheses!$B$46/12 -> 3333.3333 | J14: =Hypotheses!$B$47/12 -> 666.66667 | K14: =Hypotheses!$B$51/12 -> 500 | L14: =SUM(B14:K14) -> 16681.92 | M14: =M13+L14 -> 276835.59
... A37: 36 | B37: =IF($A37=1,Hypotheses!$B$32,0)+IF($A37<=Hypotheses!$B$28,Hypotheses!$B$29/Hypotheses!$B$28,0) -> 0 | C37: =IF($A37<=Hypotheses!$B$28,Hypotheses!$B$88/Hypotheses!$B$28,0) -> 0 | D37: =MAU_mensuel!$K37*Hypotheses!$B$36/12 -> 34000 | E37: =MAU_mensuel!$K37*Hypotheses!$B$38*Hypotheses!$B$39*Hypotheses!$B$40*Hypotheses!$B$41/1000000 -> 8160 | F37: =MAU_mensuel!$K37*Hypotheses!$B$37/12 -> 4250 | G37: =Hypotheses!$B$43/12 -> 1450 | H37: =MAU_mensuel!$K37*Hypotheses!$B$89/12 -> 2833.3333 | I37: =Hypotheses!$B$46/12 -> 3333.3333 | J37: =Hypotheses!$B$47/12 -> 666.66667 | K37: =Hypotheses!$B$51/12 -> 500 | L37: =SUM(B37:K37) -> 55193.333 | M37: =M36+L37 -> 1090780.7

Sheet Revenus
A1: Mois | B1: MAU | C1: Premium - Pess. | D1: B2B - Pess. | E1: Total - Pess. | F1: Cumul - Pess. | G1: Premium - Normal | H1: B2B - Normal | I1: Total - Normal | J1: Cumul - Normal | K1: Premium - Opti. | L1: B2B - Opti. | M1: Total - Opti. | N1: Cumul - Opti.
A2: 1 | B2: =MAU_mensuel!$K2 -> 15700 | C2: =$B2*Hypotheses!$B$21*Hypotheses!$B$16 -> 328.601 | D2: =Hypotheses!$B$22*Hypotheses!$B$18/12 -> 0 | E2: =C2+D2 -> 328.601 | F2: =E2 -> 328.601 | G2: =$B2*Hypotheses!$C$21*Hypotheses!$B$16 -> 469.43 | H2: =Hypotheses!$C$22*Hypotheses!$B$18/12 -> 2000 | I2: =G2+H2 -> 2469.43 | J2: =I2 -> 2469.43 | K2: =$B2*Hypotheses!$D$21*Hypotheses!$B$16 -> 938.86 | L2: =Hypotheses!$D$22*Hypotheses!$B$18/12 -> 5000 | M2: =K2+L2 -> 5938.86 | N2: =M2 -> 5938.86
A3: 2 | B3: =MAU_mensuel!$K3 -> 66478.302 | C3: =$B3*Hypotheses!$B$21*Hypotheses!$B$16 -> 1391.3909 | D3: =Hypotheses!$B$22*Hypotheses!$B$18/12 -> 0 | E3: =C3+D3 -> 1391.3909 | F3: =F2+E3 -> 1719.9919 | G3: =$B3*Hypotheses!$C$21*Hypotheses!$B$16 -> 1987.7012 | H3: =Hypotheses!$C$22*Hypotheses!$B$18/12 -> 2000 | I3: =G3+H3 -> 3987.7012 | J3: =J2+I3 -> 6457.1312 | K3: =$B3*Hypotheses!$D$21*Hypotheses!$B$16 -> 3975.4025 | L3: =Hypotheses!$D$22*Hypotheses!$B$18/12 -> 5000 | M3: =K3+L3 -> 8975.4025 | N3: =N2+M3 -> 14914.262
A4: 3 | B4: =MAU_mensuel!$K4 -> 111163.21 | C4: =$B4*Hypotheses!$B$21*Hypotheses!$B$16 -> 2326.6459 | D4: =Hypotheses!$B$22*Hypotheses!$B$18/12 -> 0 | E4: =C4+D4 -> 2326.6459 | F4: =F3+E4 -> 4046.6378 | G4: =$B4*Hypotheses!$C$21*Hypotheses!$B$16 -> 3323.7799 | H4: =Hypotheses!$C$22*Hypotheses!$B$18/12 -> 2000 | I4: =G4+H4 -> 5323.7799 | J4: =J3+I4 -> 11780.911 | K4: =$B4*Hypotheses!$D$21*Hypotheses!$B$16 -> 6647.5598 | L4: =Hypotheses!$D$22*Hypotheses!$B$18/12 -> 5000 | M4: =K4+L4 -> 11647.56 | N4: =N3+M4 -> 26561.822
A5: 4 | B5: =MAU_mensuel!$K5 -> 149754.72 | C5: =$B5*Hypotheses!$B$21*Hypotheses!$B$16 -> 3134.3662 | D5: =Hypotheses!$B$22*Hypotheses!$B$18/12 -> 0 | E5: =C5+D5 -> 3134.3662 | F5: =F4+E5 -> 7181.004 | G5: =$B5*Hypotheses!$C$21*Hypotheses!$B$16 -> 4477.666 | H5: =Hypotheses!$C$22*Hypotheses!$B$18/12 -> 2000 | I5: =G5+H5 -> 6477.666 | J5: =J4+I5 -> 18258.577 | K5: =$B5*Hypotheses!$D$21*Hypotheses!$B$16 -> 8955.3321 | L5: =Hypotheses!$D$22*Hypotheses!$B$18/12 -> 5000 | M5: =K5+L5 -> 13955.332 | N5: =N4+M5 -> 40517.154
A6: 5 | B6: =MAU_mensuel!$K6 -> 188346.23 | C6: =$B6*Hypotheses!$B$21*Hypotheses!$B$16 -> 3942.0865 | D6: =Hypotheses!$B$22*Hypotheses!$B$18/12 -> 0 | E6: =C6+D6 -> 3942.0865 | F6: =F5+E6 -> 11123.091 | G6: =$B6*Hypotheses!$C$21*Hypotheses!$B$16 -> 5631.5522 | H6: =Hypotheses!$C$22*Hypotheses!$B$18/12 -> 2000 | I6: =G6+H6 -> 7631.5522 | J6: =J5+I6 -> 25890.129 | K6: =$B6*Hypotheses!$D$21*Hypotheses!$B$16 -> 11263.104 | L6: =Hypotheses!$D$22*Hypotheses!$B$18/12 -> 5000 | M6: =K6+L6 -> 16263.104 | N6: =N5+M6 -> 56780.259
A7: 6 | B7: =MAU_mensuel!$K7 -> 231000 | C7: =$B7*Hypotheses!$B$21*Hypotheses!$B$16 -> 4834.83 | D7: =Hypotheses!$B$22*Hypotheses!$B$18/12 -> 0 | E7: =C7+D7 -> 4834.83 | F7: =F6+E7 -> 15957.921 | G7: =$B7*Hypotheses!$C$21*Hypotheses!$B$16 -> 6906.9 | H7: =Hypotheses!$C$22*Hypotheses!$B$18/12 -> 2000 | I7: =G7+H7 -> 8906.9 | J7: =J6+I7 -> 34797.029 | K7: =$B7*Hypotheses!$D$21*Hypotheses!$B$16 -> 13813.8 | L7: =Hypotheses!$D$22*Hypotheses!$B$18/12 -> 5000 | M7: =K7+L7 -> 18813.8 | N7: =N6+M7 -> 75594.059
A8: 7 | B8: =MAU_mensuel!$K8 -> 301500 | C8: =$B8*Hypotheses!$B$21*Hypotheses!$B$16 -> 6310.395 | D8: =Hypotheses!$B$22*Hypotheses!$B$18/12 -> 0 | E8: =C8+D8 -> 6310.395 | F8: =F7+E8 -> 22268.316 | G8: =$B8*Hypotheses!$C$21*Hypotheses!$B$16 -> 9014.85 | H8: =Hypotheses!$C$22*Hypotheses!$B$18/12 -> 2000 | I8: =G8+H8 -> 11014.85 | J8: =J7+I8 -> 45811.879 | K8: =$B8*Hypotheses!$D$21*Hypotheses!$B$16 -> 18029.7 | L8: =Hypotheses!$D$22*Hypotheses!$B$18/12 -> 5000 | M8: =K8+L8 -> 23029.7 | N8: =N7+M8 -> 98623.759
A9: 8 | B9: =MAU_mensuel!$K9 -> 368642.86 | C9: =$B9*Hypotheses!$B$21*Hypotheses!$B$16 -> 7715.695 | D9: =Hypotheses!$B$22*Hypotheses!$B$18/12 -> 0 | E9: =C9+D9 -> 7715.695 | F9: =F8+E9 -> 29984.011 | G9: =$B9*Hypotheses!$C$21*Hypotheses!$B$16 -> 11022.421 | H9: =Hypotheses!$C$22*Hypotheses!$B$18/12 -> 2000 | I9: =G9+H9 -> 13022.421 | J9: =J8+I9 -> 58834.301 | K9: =$B9*Hypotheses!$D$21*Hypotheses!$B$16 -> 22044.843 | L9: =Hypotheses!$D$22*Hypotheses!$B$18/12 -> 5000 | M9: =K9+L9 -> 27044.843 | N9: =N8+M9 -> 125668.6
A10: 9 | B10: =MAU_mensuel!$K10 -> 445857.14 | C10: =$B10*Hypotheses!$B$21*Hypotheses!$B$16 -> 9331.79 | D10: =Hypotheses!$B$22*Hypotheses!$B$18/12 -> 0 | E10: =C10+D10 -> 9331.79 | F10: =F9+E10 -> 39315.801 | G10: =$B10*Hypotheses!$C$21*Hypotheses!$B$16 -> 13331.129 | H10: =Hypotheses!$C$22*Hypotheses!$B$18/12 -> 2000 | I10: =G10+H10 -> 15331.129 | J10: =J9+I10 -> 74165.429 | K10: =$B10*Hypotheses!$D$21*Hypotheses!$B$16 -> 26662.257 | L10: =Hypotheses!$D$22*Hypotheses!$B$18/12 -> 5000 | M10: =K10+L10 -> 31662.257 | N10: =N9+M10 -> 157330.86
A11: 10 | B11: =MAU_mensuel!$K11 -> 523071.43 | C11: =$B11*Hypotheses!$B$21*Hypotheses!$B$16 -> 10947.885 | D11: =Hypotheses!$B$22*Hypotheses!$B$18/12 -> 0 | E11: =C11+D11 -> 10947.885 | F11: =F10+E11 -> 50263.686 | G11: =$B11*Hypotheses!$C$21*Hypotheses!$B$16 -> 15639.836 | H11: =Hypotheses!$C$22*Hypotheses!$B$18/12 -> 2000 | I11: =G11+H11 -> 17639.836 | J11: =J10+I11 -> 91805.265 | K11: =$B11*Hypotheses!$D$21*Hypotheses!$B$16 -> 31279.671 | L11: =Hypotheses!$D$22*Hypotheses!$B$18/12 -> 5000 | M11: =K11+L11 -> 36279.671 | N11: =N10+M11 -> 193610.53
A12: 11 | B12: =MAU_mensuel!$K12 -> 586857.14 | C12: =$B12*Hypotheses!$B$21*Hypotheses!$B$16 -> 12282.92 | D12: =Hypotheses!$B$22*Hypotheses!$B$18/12 -> 0 | E12: =C12+D12 -> 12282.92 | F12: =F11+E12 -> 62546.606 | G12: =$B12*Hypotheses!$C$21*Hypotheses!$B$16 -> 17547.029 | H12: =Hypotheses!$C$22*Hypotheses!$B$18/12 -> 2000 | I12: =G12+H12 -> 19547.029 | J12: =J11+I12 -> 111352.29 | K12: =$B12*Hypotheses!$D$21*Hypotheses!$B$16 -> 35094.057 | L12: =Hypotheses!$D$22*Hypotheses!$B$18/12 -> 5000 | M12: =K12+L12 -> 40094.057 | N12: =N11+M12 -> 233704.59
A13: 12 | B13: =MAU_mensuel!$K13 -> 654000 | C13: =$B13*Hypotheses!$B$21*Hypotheses!$B$16 -> 13688.22 | D13: =Hypotheses!$B$22*Hypotheses!$B$18/12 -> 0 | E13: =C13+D13 -> 13688.22 | F13: =F12+E13 -> 76234.826 | G13: =$B13*Hypotheses!$C$21*Hypotheses!$B$16 -> 19554.6 | H13: =Hypotheses!$C$22*Hypotheses!$B$18/12 -> 2000 | I13: =G13+H13 -> 21554.6 | J13: =J12+I13 -> 132906.89 | K13: =$B13*Hypotheses!$D$21*Hypotheses!$B$16 -> 39109.2 | L13: =Hypotheses!$D$22*Hypotheses!$B$18/12 -> 5000 | M13: =K13+L13 -> 44109.2 | N13: =N12+M13 -> 277813.79
A14: 13 | B14: =MAU_mensuel!$K14 -> 740984.13 | C14: =$B14*Hypotheses!$B$21*Hypotheses!$B$16 -> 15508.798 | D14: =Hypotheses!$B$22*Hypotheses!$B$18/12 -> 0 | E14: =C14+D14 -> 15508.798 | F14: =F13+E14 -> 91743.623 | G14: =$B14*Hypotheses!$C$21*Hypotheses!$B$16 -> 22155.425 | H14: =Hypotheses!$C$22*Hypotheses!$B$18/12 -> 2000 | I14: =G14+H14 -> 24155.425 | J14: =J13+I14 -> 157062.32 | K14: =$B14*Hypotheses!$D$21*Hypotheses!$B$16 -> 44310.851 | L14: =Hypotheses!$D$22*Hypotheses!$B$18/12 -> 5000 | M14: =K14+L14 -> 49310.851 | N14: =N13+M14 -> 327124.64
... A37: 36 | B37: =MAU_mensuel!$K37 -> 3400000 | C37: =$B37*Hypotheses!$B$21*Hypotheses!$B$16 -> 71162 | D37: =Hypotheses!$B$22*Hypotheses!$B$18/12 -> 0 | E37: =C37+D37 -> 71162 | F37: =F36+E37 -> 1070220.1 | G37: =$B37*Hypotheses!$C$21*Hypotheses!$B$16 -> 101660 | H37: =Hypotheses!$C$22*Hypotheses!$B$18/12 -> 2000 | I37: =G37+H37 -> 103660 | J37: =J36+I37 -> 1600885.9 | K37: =$B37*Hypotheses!$D$21*Hypotheses!$B$16 -> 203320 | L37: =Hypotheses!$D$22*Hypotheses!$B$18/12 -> 5000 | M37: =K37+L37 -> 208320 | N37: =N36+M37 -> 3237771.8

Sheet ROI
A1: NutriScope — TP7 : ROI à trois scénarios
A3: Résultats consolidés
A4: Scénario | B4: Revenus M12 | C4: Coûts M12 | D4: ROI M12 | E4: Revenus M24 | F4: Coûts M24 | G4: ROI M24 | H4: Revenus M36 | I4: Coûts M36 | J4: ROI M36 | K4: Mois de rentabilité (payback)
A5: Pessimiste | B5: =Revenus!F13 -> 76234.826 | C5: =Couts!M13 -> 260153.67 | D5: =(B5-C5)/C5 -> -0.70696233 | E5: =Revenus!F25 -> 398083.08 | F5: =Couts!M25 -> 554269.18 | G5: =(E5-F5)/F5 -> -0.28178746 | H5: =Revenus!F37 -> 1070220.1 | I5: =Couts!M37 -> 1090780.7 | J5: =(H5-I5)/I5 -> -0.018849444 | K5: =IFERROR(MATCH(1,B11:B46,0),"Non atteint sur 36 mois") -> Non atteint sur 36 mois
A6: Normal (central) | B6: =Revenus!J13 -> 132906.89 | C6: =Couts!M13 -> 260153.67 | D6: =(B6-C6)/C6 -> -0.4891216 | E6: =Revenus!J25 -> 616690.11 | F6: =Couts!M25 -> 554269.18 | G6: =(E6-F6)/F6 -> 0.11261844 | H6: =Revenus!J37 -> 1600885.9 | I6: =Couts!M37 -> 1090780.7 | J6: =(H6-I6)/I6 -> 0.46765142 | K6: =IFERROR(MATCH(1,C11:C46,0),"Non atteint sur 36 mois") -> 22
A7: Optimiste | B7: =Revenus!N13 -> 277813.79 | C7: =Couts!M13 -> 260153.67 | D7: =(B7-C7)/C7 -> 0.067883391 | E7: =Revenus!N25 -> 1257380.2 | F7: =Couts!M25 -> 554269.18 | G7: =(E7-F7)/F7 -> 1.2685371 | H7: =Revenus!N37 -> 3237771.8 | I7: =Couts!M37 -> 1090780.7 | J7: =(H7-I7)/I7 -> 1.9683067 | K7: =IFERROR(MATCH(1,D11:D46,0),"Non atteint sur 36 mois") -> 12
A9: Mois de rentabilité (payback) — détail par scénario
A10: Mois | B10: Cumul rentable ? (Pessimiste) | C10: Cumul rentable ? (Normal (central)) | D10: Cumul rentable ? (Optimiste)
A11: 1 | B11: =IF(Revenus!F2>=Couts!M2,1,0) -> 0 | C11: =IF(Revenus!J2>=Couts!M2,1,0) -> 0 | D11: =IF(Revenus!N2>=Couts!M2,1,0) -> 0
A12: 2 | B12: =IF(Revenus!F3>=Couts!M3,1,0) -> 0 | C12: =IF(Revenus!J3>=Couts!M3,1,0) -> 0 | D12: =IF(Revenus!N3>=Couts!M3,1,0) -> 0
A13: 3 | B13: =IF(Revenus!F4>=Couts!M4,1,0) -> 0 | C13: =IF(Revenus!J4>=Couts!M4,1,0) -> 0 | D13: =IF(Revenus!N4>=Couts!M4,1,0) -> 0
A14: 4 | B14: =IF(Revenus!F5>=Couts!M5,1,0) -> 0 | C14: =IF(Revenus!J5>=Couts!M5,1,0) -> 0 | D14: =IF(Revenus!N5>=Couts!M5,1,0) -> 0
A15: 5 | B15: =IF(Revenus!F6>=Couts!M6,1,0) -> 0 | C15: =IF(Revenus!J6>=Couts!M6,1,0) -> 0 | D15: =IF(Revenus!N6>=Couts!M6,1,0) -> 0
A16: 6 | B16: =IF(Revenus!F7>=Couts!M7,1,0) -> 0 | C16: =IF(Revenus!J7>=Couts!M7,1,0) -> 0 | D16: =IF(Revenus!N7>=Couts!M7,1,0) -> 0
A17: 7 | B17: =IF(Revenus!F8>=Couts!M8,1,0) -> 0 | C17: =IF(Revenus!J8>=Couts!M8,1,0) -> 0 | D17: =IF(Revenus!N8>=Couts!M8,1,0) -> 0
A18: 8 | B18: =IF(Revenus!F9>=Couts!M9,1,0) -> 0 | C18: =IF(Revenus!J9>=Couts!M9,1,0) -> 0 | D18: =IF(Revenus!N9>=Couts!M9,1,0) -> 0
A19: 9 | B19: =IF(Revenus!F10>=Couts!M10,1,0) -> 0 | C19: =IF(Revenus!J10>=Couts!M10,1,0) -> 0 | D19: =IF(Revenus!N10>=Couts!M10,1,0) -> 0
A20: 10 | B20: =IF(Revenus!F11>=Couts!M11,1,0) -> 0 | C20: =IF(Revenus!J11>=Couts!M11,1,0) -> 0 | D20: =IF(Revenus!N11>=Couts!M11,1,0) -> 0
A21: 11 | B21: =IF(Revenus!F12>=Couts!M12,1,0) -> 0 | C21: =IF(Revenus!J12>=Couts!M12,1,0) -> 0 | D21: =IF(Revenus!N12>=Couts!M12,1,0) -> 0
A22: 12 | B22: =IF(Revenus!F13>=Couts!M13,1,0) -> 0 | C22: =IF(Revenus!J13>=Couts!M13,1,0) -> 0 | D22: =IF(Revenus!N13>=Couts!M13,1,0) -> 1
... A46: 36 | B46: =IF(Revenus!F37>=Couts!M37,1,0) -> 0 | C46: =IF(Revenus!J37>=Couts!M37,1,0) -> 1 | D46: =IF(Revenus!N37>=Couts!M37,1,0) -> 1
A49: Courbe des cumuls — coûts vs revenus (3 scénarios), 36 mois

Sheet KPI
A1: KPI produit | B1: Définition / mode de calcul | C1: Baseline | D1: Cible (datée) | E1: Source de mesure | F1: Fréquence | G1: Seuil d'alerte | H1: Pourquoi ce seuil (résumé) | I1: Responsable
A2: Scans par jour actif | B2: Nombre moyen de scans réalisés par utilisateur actif et par jour | C2: n/a (pré-lancement) | D2: ≥ 1,5 scan/j actif à M6 | E2: Journaux applicatifs (API) | F2: Hebdomadaire | G2: < 0,8 scan/j actif | H2: En dessous de 0,8, la moyenne des utilisateurs actifs n'atteint même plus le minimum d'une session de courses hebdomadaire type (plusieurs scans par passage en rayon). | I2: Responsable produit
A3: Taux d'activation à J7 | B3: Part des nouveaux inscrits ayant scanné au moins un produit dans les 7 jours suivant l'inscription | C3: n/a (pré-lancement) | D3: ≥ 60 % à M6 | E3: Mesure d'usage produit | F3: Hebdomadaire | G3: < 40 % | H3: Le persona principal (Sophie, parent pressé) fait ses courses environ une fois par semaine : sous 40 %, la majorité des inscrits n'atteint jamais le moment de vérité en rayon dans son premier cycle de courses. | I3: Croissance / Marketing
A4: Rétention à 30 jours | B4: Part des utilisateurs actifs au mois M qui reviennent au mois M+1 | C4: n/a (pré-lancement) | D4: ≥ 40 % à M12 (objectif SMART du cahier des charges) | E4: Mesure d'usage produit | F4: Mensuelle | G4: < 20 % | H4: Sous 20 %, plus de 8 utilisateurs sur 10 abandonnent après un mois : le modèle d'abonnement mensuel Premium, qui suppose un usage récurrent pour être perçu comme utile, devient alors structurellement injustifiable. | I4: Responsable produit
A5: Taux de substitution acceptée | B5: Part des recommandations de substitution effectivement retenues par l'utilisateur (clic + confirmation) | C5: n/a (pré-lancement) | D5: ≥ 15 % à M12 | E5: Journaux du moteur de substitution | F5: Mensuelle | G5: < 8 % | H5: Le moteur de substitution est le premier différenciant cité dans benchmark.md face à Yuka/Foodvisor : sous 8 %, il ne serait utilisé que par une minorité marginale, ce qui invaliderait cet axe du cahier des charges (brique 3). Condition technique nécessaire (pas suffisante) : la précision du moteur (précision@3) doit rester ≥ 85-90 %, hypothèse fixée en direction le 15/09 — voir onglet Hypotheses_fragiles et note d'hypothèses §3. | I5: Responsable data / IA
A6: Taux de réponses assistant sourcées | B6: Part des réponses de l'assistant conversationnel appuyées sur une donnée produit identifiée (pas d'information inventée) | C6: n/a (pré-lancement) | D6: ≥ 90 % dès la mise en production | E6: Contrôle qualité de l'assistant (échantillon hebdomadaire) | F6: Hebdomadaire | G6: < 80 % | H6: US-04 du cahier des charges impose un assistant « sans hallucination ». Sous 80 %, une réponse sur cinq n'est plus vérifiée : le risque de perte de confiance identifié dans opportunite.md (risque R6) devient statistiquement visible pour l'utilisateur. | I6: Responsable data / IA
A7: Coût par requête assistant | B7: Coût moyen (consommation du modèle de langage) d'une conversation avec l'assistant conversationnel | C7: n/a (pré-lancement) | D7: ≤ 0,02 € / conversation | E7: Suivi des coûts d'API du modèle de langage | F7: Mensuelle | G7: > 0,03 € | H7: Ce seuil découle directement du modèle de coûts du tableur : à 4 000 jetons/conversation, le coût actuel est d'environ 0,008 €. Au-delà de 0,03 € (~4× l'hypothèse retenue), le poste « Run - LLM » menacerait la rentabilité déjà tendue du scénario normal (conversion à 1 %). | I7: Responsable données / infrastructure

Sheet Hypotheses_fragiles
A1: Hypothèse | B1: Pourquoi elle est fragile | C1: Impact si elle est fausse | D1: Comment la vérifier tôt | E1: Jalon de vérification
A2: Taux de conversion Premium (0,7 % à 3 %, arbitré en direction) | B2: Aucun essai réel de vente de l'abonnement n'a encore été mené ; c'est une hypothèse resserrée par prudence après échange avec la direction, sans donnée d'usage pour la confirmer. | C2: C'est le levier qui fait le plus varier le résultat : voir le tableau des ROI (§4 de la note) pour l'écart entre scénarios. | D2: Présenter l'offre payante (description + bouton d'abonnement, sans encaissement réel) à un groupe test de 200 à 300 utilisateurs avant le lancement public, et mesurer le taux d'intérêt réel. | E2: Avant J3 (MVP)
A3: Nombre et vitesse de signature des contrats B2B (0 à 5, 12 000 €/an chacun) | B3: Aucun distributeur n'est engagé à ce jour ; le cycle de vente B2B (juridique, RGPD, intégration technique) est long et non maîtrisé par l'équipe. | C3: Représente jusqu'à 60 000 € de revenus en scénario optimiste, soit une part importante des revenus de l'Année 1. | D3: Prendre contact avec 3 à 5 distributeurs ou enseignes cibles dès le mois 2 pour valider l'intérêt et le montant avant de l'inscrire au budget. | E3: Avant J2 / J3
A4: Budget d'acquisition (40 000 €/an) et sa capacité à produire la trajectoire MAU (654 k à M12) | B4: La trajectoire MAU du TP1 est un objectif, pas une donnée observée : elle suppose un coût d'acquisition par utilisateur qui n'a jamais été mesuré en conditions réelles. | C4: Si le coût réel d'acquisition est supérieur à l'hypothèse, soit le budget de communication doit augmenter, soit la trajectoire MAU — et donc tous les revenus — ne se réalise pas. | D4: Suivre le coût d'acquisition réel dès les premières campagnes test (mois 1-2) et le comparer à l'hypothèse implicite ; recalculer la trajectoire si l'écart dépasse 20 %. | E4: Avant J1 / J2
